Workbook

Sheet Titre
A1: MON PETIT CAMION PIZZA

Sheet Lancement blank
A1: LANCEMENT DE L'ACTIVITE LE 20 DECEMBRE
B4: Je crée mon entreprise en y investissant une partie de mes économies : | F4: 5000
B5: Le 22 décembre, j'approvisionne les matières nécessaires pour les ventes de janvier :
B6: - Achats matières : | C6: 750
B7: Je passe d'excellentes fêtes de fin d'année en famille, dans l'attente de commencer à opérer en janvier !
B11: TABLEAU DES FLUX DE TRESORERIE
B13: Disponibilités de début
B15: Entrées de trésorerie
B16: Capital social
B18: Sorties de trésorerie
B19: Achats matières
B21: Disponibilités de fin
B24: BILAN FIN DECEMBRE
B26: ACTIF | E26: PASSIF
B27: Stock | E27: Capital social
B28: Disponibilités
B29: Total actif | E29: Total passif

Sheet Lancement
A1: LANCEMENT DE L'ACTIVITE LE 20 DECEMBRE
B4: Je crée mon entreprise en y investissant une partie de mes économies : | F4: 5000
B5: Le 22 décembre, j'approvisionne les matières nécessaires pour les ventes de janvier :
B6: - Achats matières : | C6: 750
B7: Je passe d'excellentes fêtes de fin d'année en famille, dans l'attente de commencer à opérer en janvier !
B11: TABLEAU DES FLUX DE TRESORERIE
B13: Disponibilités de début | C13: 0
B15: Entrées de trésorerie
B16: Capital social | C16: =F4 -> 5000
B18: Sorties de trésorerie
B19: Achats matières | C19: =C6 -> 750
B21: Disponibilités de fin | C21: =C13+C16-C19 -> 4250
B24: BILAN FIN DECEMBRE
B26: ACTIF | E26: PASSIF
B27: Stock | C27: =C6 -> 750 | E27: Capital social | F27: =F4 -> 5000
B28: Disponibilités | C28: =C21 -> 4250
B29: Total actif | C29: =SUM(C27:C28) -> 5000 | E29: Total passif | F29: =F27 -> 5000

Sheet Janvier blank
A1: JANVIER
B4: Je loue mon camion : | C4: 2500
B5: Je vends : | C5: 500
B6: Le prix de vente est de : | C6: 10 | D6: (tous les clients paient comptant)
B7: Hormis la location du camion, les dépenses à prendre en compte sont les suivantes :
B8: - Matière : | C8: =Lancement!C27/'Janvier blank'!C5 -> 1.5 | D8: (achetée en décembre)
B9: - Eau & Electricité : | C9: 0.5
B12: TABLEAU DES FLUX DE TRESORERIE
B14: Disponibilités de début
B16: Entrées de trésorerie
B17: Ventes au comptant
B19: Sorties de trésorerie
B20: Eau & Electricité
B21: Location camion
B23: Disponibilités de fin
B26: COMPTE DE RESULTAT | E26: COUT DE REVIENT D'UNE PIZZA
B28: Chiffre d'affaires | E28: Matière
B29: - Coût des pizzas vendues | E29: Eau & Electricité
B30: - Location du camion | E30: Total
B31: Bénéfice mensuel
B34: BILAN FIN DE MOIS
B36: ACTIF | E36: PASSIF
B37: Stock | E37: Capital social
B38: Disponibilités | E38: Bénéfice janvier
B39: Total actif | E39: Total passif
B42: COMBIEN DOIS-JE VENDRE DE PIZZAS POUR COUVRIR LES FRAIS FIXES ?
B44: Point d'équilibre :

Sheet Janvier
A1: JANVIER
B4: Je loue mon camion : | C4: 2500
B5: Je vends : | C5: 500
B6: Le prix de vente est de : | C6: 10 | D6: (tous les clients paient comptant)
B7: Hormis la location du camion, les dépenses à prendre en compte sont les suivantes :
B8: - Matière : | C8: =Lancement!C27/Janvier!C5 -> 1.5 | D8: (achetée en décembre)
B9: - Eau & Electricité : | C9: 0.5
B12: TABLEAU DES FLUX DE TRESORERIE
B14: Disponibilités de début | C14: =Lancement!C28 -> 4250
B16: Entrées de trésorerie
B17: Ventes au comptant | C17: =C28 -> 5000
B19: Sorties de trésorerie
B20: Eau & Electricité | C20: =C9*C5 -> 250
B21: Location camion | C21: =C4 -> 2500
B23: Disponibilités de fin | C23: =C14+SUM(C16:C17)-SUM(C19:C21) -> 6500
B26: COMPTE DE RESULTAT | E26: COUT DE REVIENT D'UNE PIZZA
B28: Chiffre d'affaires | C28: =C5*C6 -> 5000 | E28: Matière | F28: =C8 -> 1.5
B29: - Coût des pizzas vendues | C29: =-F30*C5 -> -1000 | E29: Eau & Electricité | F29: =C9 -> 0.5
B30: - Location du camion | C30: =-C4 -> -2500 | E30: Total | F30: =SUM(F28:F29) -> 2
B31: Bénéfice mensuel | C31: =SUM(C28:C30) -> 1500
B34: BILAN FIN DE MOIS
B36: ACTIF | E36: PASSIF
B37: Stock | C37: =Lancement!C27-Janvier!F28*Janvier!C5 -> 0 | E37: Capital social | F37: =Lancement!F27 -> 5000
B38: Disponibilités | C38: =C23 -> 6500 | E38: Bénéfice janvier | F38: =C31 -> 1500
B39: Total actif | C39: =SUM(C37:C38) -> 6500 | E39: Total passif | F39: =SUM(F37:F38) -> 6500
B42: COMBIEN DOIS-JE VENDRE DE PIZZAS POUR COUVRIR LES FRAIS FIXES ?
B44: Point d'équilibre : | C44: =-C30/(C6-F30) -> 312.5

Sheet Fevrier blank
A1: FEVRIER
B4: Je loue mon camion : | C4: 2500
B5: Je vends : | C5: 1000 | D5: à des clients particuliers qui paient comptant.
B6: Je vends aussi : | C6: 2000 | D6: avec une entreprise locale (paiement à 30 jours).
B7: Le prix de vente est de : | C7: 10 | D7: quel que soit le type de client.
B8: Hormis la location du camion, les dépenses à prendre en compte sont les suivantes :
B9: - Achat matière : | C9: 5000 | D9: (coût matière/pizza identique au mois précédent)
B10: - Eau & Electricité : | C10: 0.5
B11: - Salarié à mi-temps : | C11: 1000
B14: TABLEAU DES FLUX DE TRESORERIE
B16: Disponibilités de début
B18: Entrées de trésorerie
B19: Ventes au comptant
B21: Sorties de trésorerie
B22: Achat matière
B23: Eau & Electricité
B24: Salarié
B25: Location camion
B27: Disponibilités de fin
B30: COMPTE DE RESULTAT | E30: COUT DE REVIENT D'UNE PIZZA
B32: Chiffre d'affaires | E32: Matière
B33: - Coût des pizzas vendues | E33: Eau & Electricité
B34: - Salarié | E34: Total
B35: - Location du camion
B36: Bénéfice mensuel
B39: BILAN FIN DE MOIS
B41: ACTIF | E41: PASSIF
B42: Stock | E42: Capital social
B43: Créances clients | E43: Bénéfice janvier
B44: Disponibilités | E44: Bénéfice février
B45: Total actif | E45: Total passif

Sheet Fevrier
A1: FEVRIER
B4: Je loue mon camion : | C4: 2500
B5: Je vends : | C5: 1000 | D5: à des clients particuliers qui paient comptant.
B6: Je vends aussi : | C6: 2000 | D6: avec une entreprise locale (paiement à 30 jours).
B7: Le prix de vente est de : | C7: 10 | D7: quel que soit le type de client.
B8: Hormis la location du camion, les dépenses à prendre en compte sont les suivantes :
B9: - Achat matière : | C9: 5000 | D9: (coût matière/pizza identique au mois précédent)
B10: - Eau & Electricité : | C10: 0.5
B11: - Salarié à mi-temps : | C11: 1000
B14: TABLEAU DES FLUX DE TRESORERIE
B16: Disponibilités de début | C16: =Janvier!C38 -> 6500
B18: Entrées de trésorerie
B19: Ventes au comptant | C19: =C5*C7 -> 10000
B21: Sorties de trésorerie
B22: Achat matière | C22: =C9 -> 5000
B23: Eau & Electricité | C23: =C10*(C5+C6) -> 1500
B24: Salarié | C24: =C11 -> 1000
B25: Location camion | C25: =C4 -> 2500
B27: Disponibilités de fin | C27: =C16+SUM(C18:C19)-SUM(C21:C25) -> 6500
B30: COMPTE DE RESULTAT | E30: COUT DE REVIENT D'UNE PIZZA
B32: Chiffre d'affaires | C32: =(C5+C6)*C7 -> 30000 | E32: Matière | F32: =Janvier!C8 -> 1.5
B33: - Coût des pizzas vendues | C33: =-F34*(C5+C6) -> -6000 | E33: Eau & Electricité | F33: =C10 -> 0.5
B34: - Salarié | C34: =-C11 -> -1000 | E34: Total | F34: =SUM(F32:F33) -> 2
B35: - Location du camion | C35: =-C4 -> -2500
B36: Bénéfice mensuel | C36: =SUM(C32:C35) -> 20500
B39: BILAN FIN DE MOIS
B41: ACTIF | E41: PASSIF
B42: Stock | C42: =Janvier!C37+Fevrier!C9-Fevrier!F32*(Fevrier!C5+Fevrier!C6) -> 500 | E42: Capital social | F42: =Lancement!F27 -> 5000
B43: Créances clients | C43: =C6*C7 -> 20000 | E43: Bénéfice janvier | F43: =Janvier!F38 -> 1500
B44: Disponibilités | C44: =C27 -> 6500 | E44: Bénéfice février | F44: =C36 -> 20500
B45: Total actif | C45: =SUM(C42:C44) -> 27000 | E45: Total passif | F45: =SUM(F42:F44) -> 27000

Sheet Mars blank
A1: MARS
B4: J'achète le camion : | C4: 36000 | D4: (payable 50% en mars, 50% en avril fin de mois)
B5: Je vends : | C5: 1000 | D5: à des clients particuliers qui paient comptant.
B6: Je vends aussi : | C6: 2000 | D6: avec une entreprise locale (paiement à 30 jours).
B7: Le prix de vente est de : | C7: 10 | D7: quel que soit le type de client.
B8: Hormis la location du camion, les coûts à prendre en compte sont les suivants :
B9: - Achat matière : | C9: 5000 | D9: (coût matière/pizza identique au mois précédent)
B10: - Eau & Electricité : | C10: 0.5
B11: - Salarié à mi-temps : | C11: 1000
B12: - Assurance du camion : | C12: 300
B13: Durée d'amortissement : | C13: 3 | D13: pour la totalité de la valeur du camion
B16: TABLEAU DES FLUX DE TRESORERIE
B18: Disponibilités de début
B20: Entrées de trésorerie
B21: Collecte créances clients
B22: Ventes au comptant
B24: Sorties de trésorerie
B25: Achat camion
B26: Achat matière
B27: Eau & Electricité
B28: Salarié
B29: Assurance camion
B31: Disponibilités de fin
B34: COMPTE DE RESULTAT | E34: COUT DE REVIENT D'UNE PIZZA
B36: Chiffre d'affaires | E36: Matière
B37: - Coût des pizzas vendues | E37: Eau & Electricité
B38: - Salarié | E38: Total
B39: - Assurance camion
B40: - Amortissement camion
B41: Bénéfice mensuel
B44: BILAN FIN DE MOIS
B46: ACTIF | E46: PASSIF
B47: Valeur brute du camion | E47: Capital social
B48: - Amortissements cumulés | E48: Réserves
B49: Valeur nette du camion | E49: Bénéfice mars
B50: Stock | E50: Capitaux propres
B51: Créances clients
B52: Disponibilités | E52: Dette fourniss. camion
B53: Total actif | E53: Total passif

Sheet Mars
A1: MARS
B4: J'achète le camion : | C4: 36000 | D4: (payable 50% en mars, 50% en avril fin de mois)
B5: Je vends : | C5: 1000 | D5: à des clients particuliers qui paient comptant.
B6: Je vends aussi : | C6: 2000 | D6: avec une entreprise locale (paiement à 30 jours).
B7: Le prix de vente est de : | C7: 10 | D7: quel que soit le type de client.
B8: Hormis la location du camion, les coûts à prendre en compte sont les suivants :
B9: - Achat matière : | C9: 5000 | D9: (coût matière/pizza identique au mois précédent)
B10: - Eau & Electricité : | C10: 0.5
B11: - Salarié à mi-temps : | C11: 1000
B12: - Assurance du camion : | C12: 300
B13: Durée d'amortissement : | C13: 3 | D13: pour la totalité de la valeur du camion
B16: TABLEAU DES FLUX DE TRESORERIE
B18: Disponibilités de début | C18: =Fevrier!C44 -> 6500
B20: Entrées de trésorerie
B21: Collecte créances clients | C21: =Fevrier!C43 -> 20000
B22: Ventes au comptant | C22: =C5*C7 -> 10000
B24: Sorties de trésorerie
B25: Achat camion | C25: =0.5*C4 -> 18000
B26: Achat matière | C26: =C9 -> 5000
B27: Eau & Electricité | C27: =C10*(C5+C6) -> 1500
B28: Salarié | C28: =C11 -> 1000
B29: Assurance camion | C29: =C12 -> 300
B31: Disponibilités de fin | C31: =C18+SUM(C20:C22)-SUM(C24:C29) -> 10700
B34: COMPTE DE RESULTAT | E34: COUT DE REVIENT D'UNE PIZZA
B36: Chiffre d'affaires | C36: =SUM(C5:C6)*C7 -> 30000 | E36: Matière | F36: =Fevrier!F32 -> 1.5
B37: - Coût des pizzas vendues | C37: =-F38*SUM(C5:C6) -> -6000 | E37: Eau & Electricité | F37: =C10 -> 0.5
B38: - Salarié | C38: =-C11 -> -1000 | E38: Total | F38: =SUM(F36:F37) -> 2
B39: - Assurance camion | C39: =-C12 -> -300
B40: - Amortissement camion | C40: =-C4/C13/12 -> -1000
B41: Bénéfice mensuel | C41: =SUM(C36:C40) -> 21700
B44: BILAN FIN DE MOIS
B46: ACTIF | E46: PASSIF
B47: Valeur brute du camion | C47: =C4 -> 36000 | E47: Capital social | F47: =Fevrier!F42 -> 5000
B48: - Amortissements cumulés | C48: =C40 -> -1000 | E48: Réserves | F48: =SUM(Fevrier!F43:F44) -> 22000
B49: Valeur nette du camion | C49: =SUM(C47:C48) -> 35000 | E49: Bénéfice mars | F49: =C41 -> 21700
B50: Stock | C50: =Fevrier!C42+Mars!C9-(Mars!C5+Mars!C6)*Mars!F36 -> 1000 | E50: Capitaux propres | F50: =SUM(F47:F49) -> 48700
B51: Créances clients | C51: =C6*C7 -> 20000
B52: Disponibilités | C52: =C31 -> 10700 | E52: Dette fourniss. camion | F52: =C4-C25 -> 18000
B53: Total actif | C53: =SUM(C49:C52) -> 66700 | E53: Total passif | F53: =SUM(F50:F52) -> 66700

Sheet Avril blank
A1: AVRIL
B4: Je vends : | C4: 4000 | D4: avec une entreprise locale (paiement à 60 jours).
B5: Le prix de vente est de : | C5: 10 | D5: quel que soit le type de client.
B6: Hormis la location du camion, les coûts à prendre en compte sont les suivants :
B7: - Achat matière : | C7: 5000 | D7: (coût matière/pizza identique au mois précédent)
B8: - Eau & Electricité : | C8: 0.5
B9: - Salarié à mi-temps : | C9: 1000
B10: - Assurance du camion : | C10: 300
B11: Durée d'amortissement : | C11: 3 | D11: pour le camion
B14: TABLEAU DES FLUX DE TRESORERIE
B16: Disponibilités de début
B18: Entrées de trésorerie
B19: Collecte créances clients
B20: Ventes au comptant
B22: Sorties de trésorerie
B23: Fin paiement camion
B24: Achat matière
B25: Eau & Electricité
B26: Salarié
B27: Assurance camion
B29: Disponibilités de fin
B32: COMPTE DE RESULTAT | E32: COUT DE REVIENT D'UNE PIZZA
B34: Chiffre d'affaires | E34: Matière
B35: - Coût des pizzas vendues | E35: Eau & Electricité
B36: - Salarié | E36: Total
B37: - Assurance camion
B38: - Amortissement camion
B39: Bénéfice mensuel
B42: BILAN FIN DE MOIS
B44: ACTIF | E44: PASSIF
B45: Valeur brute du camion | E45: Capital social
B46: - Amortissements cumulés | E46: Réserves
B47: Valeur nette du camion | E47: Bénéfice avril
B48: Stock | E48: Capitaux propres
B49: Créances clients
B50: Disponibilités | E50: Dette fourniss. camion
B51: Total actif | E51: Total passif

Sheet Avril
A1: AVRIL
B4: Je vends : | C4: 4000 | D4: avec une entreprise locale (paiement à 60 jours).
B5: Le prix de vente est de : | C5: 10 | D5: quel que soit le type de client.
B6: Hormis la location du camion, les coûts à prendre en compte sont les suivants :
B7: - Achat matière : | C7: 5000 | D7: (coût matière/pizza identique au mois précédent)
B8: - Eau & Electricité : | C8: 0.5
B9: - Salarié à mi-temps : | C9: 1000
B10: - Assurance du camion : | C10: 300
B11: Durée d'amortissement : | C11: 3 | D11: pour le camion
B14: TABLEAU DES FLUX DE TRESORERIE
B16: Disponibilités de début | C16: =Mars!C52 -> 10700
B18: Entrées de trésorerie
B19: Collecte créances clients | C19: =Mars!C51 -> 20000
B20: Ventes au comptant | C20: 0
B22: Sorties de trésorerie
B23: Fin paiement camion | C23: =Mars!F52 -> 18000
B24: Achat matière | C24: =C7 -> 5000
B25: Eau & Electricité | C25: =C8*C4 -> 2000
B26: Salarié | C26: =C9 -> 1000
B27: Assurance camion | C27: =C10 -> 300
B29: Disponibilités de fin | C29: =C16+SUM(C18:C20)-SUM(C22:C27) -> 4400
B32: COMPTE DE RESULTAT | E32: COUT DE REVIENT D'UNE PIZZA
B34: Chiffre d'affaires | C34: =SUM(C4:C4)*C5 -> 40000 | E34: Matière | F34: =Mars!F36 -> 1.5 | H34: Marge opérationnelle : | J34: =C39/C34 -> 0.7425
B35: - Coût des pizzas vendues | C35: =-F36*SUM(C4:C4) -> -8000 | E35: Eau & Electricité | F35: =C8 -> 0.5
B36: - Salarié | C36: =-C9 -> -1000 | E36: Total | F36: =SUM(F34:F35) -> 2
B37: - Assurance camion | C37: =-C10 -> -300
B38: - Amortissement camion | C38: =Mars!C40 -> -1000
B39: Bénéfice mensuel | C39: =SUM(C34:C38) -> 29700
B42: BILAN FIN DE MOIS
B44: ACTIF | E44: PASSIF
B45: Valeur brute du camion | C45: =Mars!C47 -> 36000 | E45: Capital social | F45: =Fevrier!F42 -> 5000
B46: - Amortissements cumulés | C46: =Mars!C48+Avril!C38 -> -2000 | E46: Réserves | F46: =Mars!F48+Mars!F49 -> 43700
B47: Valeur nette du camion | C47: =SUM(C45:C46) -> 34000 | E47: Bénéfice avril | F47: =C39 -> 29700
B48: Stock | C48: =Mars!C50+Avril!C7-Avril!C4*Avril!F34 -> 0 | E48: Capitaux propres | F48: =SUM(F45:F47) -> 78400
B49: Créances clients | C49: =C4*C5 -> 40000
B50: Disponibilités | C50: =C29 -> 4400 | E50: Dette fourniss. camion | F50: 0
B51: Total actif | C51: =SUM(C47:C50) -> 78400 | E51: Total passif | F51: =SUM(F48:F50) -> 78400

Sheet Mai blank
A1: MAI
A4: 1/ | B4: Je vends : | C4: 5000 | D4: à une entreprise locale
B5: Prix de vente : | C5: 10
B6: Délais de paiement client : | C6: 60
A8: 2/ | B8: Je me rends au supermarché pour acheter des matières premières :
B9: Achat matière : | C9: 8000 | D9: (paiement 50% comptant & 50% le mois suivant)
A11: 3/ | B11: Je dois aussi supporter les coûts suivants :
B12: Coût matière : | C12: 1.5
B13: Eau & électricité : | C13: 0.5
B14: Salarié à mi-temps : | C14: 1000
B15: Assurance du camion : | C15: 300
A17: 4/ | B17: Au début du mois, je contracte un prêt auprès de Alpha-Bank :
B18: Montant emprunté : | C18: 20000 | D18: (principal de l'emprunt)
B19: Taux d'intérêt : | C19: 0.01 | D19: par mois
A21: 5/ | B21: Je commence à payer des impôts sur mes bénéfices :
B22: Taux d'imposition : | C22: =1/3 -> 0.33333333
B24: COÛT DE REVIENT D'UNE PIZZA | E24: COMPTE DE RESULTAT | H24: BILAN FIN DE MOIS | K24: TABLEAU DES FLUX DE TRESORERIE
B26: Matière | C26: =C12 -> 1.5 | E26: Chiffre d'affaires | F26: =C4*C5 -> 50000 | H26: ACTIF | K26: Disponibilités de début | L26: =Avril!C50 -> 4400
B27: Eau & Electricité | C27: =C13 -> 0.5 | E27: - Coût des pizzas vendues | F27: =-C4*C28 -> -10000 | H27: Valeur brute du camion | I27: =Avril!C45 -> 36000
B28: Total | C28: =SUM(C26:C27) -> 2 | E28: Marge sur coûts variables | F28: =SUM(F26:F27) -> 40000 | H28: - Amortissements cumulés | I28: =Avril!C46+F32 -> -3000 | K28: EBITDA | L28: =F31 -> 38700
E29: - Salarié | F29: =-C14 -> -1000 | H29: Valeur nette du camion | I29: =I27+I28 -> 33000 | K29: - Augmentation des stocks | L29: =-(I30-Avril!C48) -> -500
E30: - Assurance camion | F30: =-C15 -> -300 | H30: Stocks | I30: =Avril!C48+C9-C12*C4 -> 500 | K30: - Augmentation des créances clients | L30: =-(I33-Avril!C49) -> -50000
E31: EBITDA | F31: =SUM(F28:F30) -> 38700 | H31: Créances clients avril | I31: =Avril!C49 -> 40000 | K31: + Augmentation des dettes fournisseurs | L31: =I44-Avril!F50 -> 4000
E32: - Amortissement camion | F32: =Avril!C38 -> -1000 | H32: Créances clients mai | I32: =F26 -> 50000 | K32: - Impôts | L32: =F36 -> -12500
E33: EBIT (Résultat d'exploitation) | F33: =SUM(F31:F32) -> 37700 | H33: Créances clients (total) | I33: =I31+I32 -> 90000 | K33: Flux de trésorerie d'exploitation | L33: =SUM(L28:L32) -> -20300
E34: - Intérêts d'emprunt | F34: =-C18*C19 -> -200 | H34: Disponibilités | I34: =L43 -> 3900
E35: Bénéfice avant impôts | F35: =SUM(F33:F34) -> 37500 | H35: Total actif | I35: =I29+I30+I33+I34 -> 127400 | K35: Flux de trésorerie d'investissement | L35: 0
E36: - Impôts | F36: =-C22*F35 -> -12500
E37: Bénéfice net mensuel | F37: =SUM(F35:F36) -> 25000 | K37: Emprunt auprès d'Alpha-Bank | L37: =C18 -> 20000
H38: PASSIF | K38: Intérêts d'emprunt | L38: =F34 -> -200
E39: EBITDA: Earnings Before Interest, Tax, Depreciation & Amortization | H39: Capital social | I39: =Avril!F45 -> 5000 | K39: Flux de trésorerie de financement | L39: =SUM(L37:L38) -> 19800
E40: EBIT: Earnings Before Interest & Tax | H40: Réserves | I40: =Avril!F46+Avril!F47 -> 73400
H41: Bénéfice net mensuel | I41: =F37 -> 25000 | K41: Flux de trésorerie total | L41: =L33+L35+L39 -> -500
H42: Capitaux propres | I42: =SUM(I39:I41) -> 103400
H43: Emprunt auprès d'Alpha-Bank | I43: =C18 -> 20000 | K43: Disponibilités de fin | L43: =L26+L41 -> 3900
H44: Dettes fournisseurs | I44: =C9/2 -> 4000
H45: Total passif | I45: =I42+I43+I44 -> 127400
E49: Marge opérationnelle | F49: =F33/F26 -> 0.754 | H49: Ressources employées par l'exploitation : | K49: EBIT * (1-Taux imposition) | L49: =F33*(1-C22) -> 25133.333
H50: =H29 -> Valeur nette du camion | I50: =I29 -> 33000 | K50: + Amortissement | L50: =-F32 -> 1000
H51: Stocks | I51: =I30 -> 500 | K51: - Investissement dans BFR | L51: =-(I54-(Avril!C48+Avril!C49-Avril!F50)) -> -46500
...

Sheet Mai
A1: MAI
A4: 1/ | B4: Je vends : | C4: 5000 | D4: à une entreprise locale
B5: Prix de vente : | C5: 10
B6: Délais de paiement client : | C6: 60
A8: 2/ | B8: Je me rends au supermarché pour acheter des matières premières :
B9: Achat matière : | C9: 8000 | D9: (paiement 50% comptant & 50% le mois suivant)
A11: 3/ | B11: Je dois aussi supporter les coûts suivants :
B12: Coût matière : | C12: 1.5
B13: Eau & électricité : | C13: 0.5
B14: Salarié à mi-temps : | C14: 1000
B15: Assurance du camion : | C15: 300
A17: 4/ | B17: Au début du mois, je contracte un prêt auprès de Alpha-Bank :
B18: Montant emprunté : | C18: 20000 | D18: (principal de l'emprunt)
B19: Taux d'intérêt : | C19: 0.01 | D19: par mois
A21: 5/ | B21: Je commence à payer des impôts sur mes bénéfices :
B22: Taux d'imposition : | C22: =1/3 -> 0.33333333
B24: COÛT DE REVIENT D'UNE PIZZA | E24: COMPTE DE RESULTAT | H24: BILAN FIN DE MOIS | K24: TABLEAU DES FLUX DE TRESORERIE
B26: Matière | C26: =C12 -> 1.5 | E26: Chiffre d'affaires | F26: =C4*C5 -> 50000 | H26: ACTIF | K26: Disponibilités de début | L26: =Avril!C50 -> 4400
B27: Eau & Electricité | C27: =C13 -> 0.5 | E27: - Coût des pizzas vendues | F27: =-C4*C28 -> -10000 | H27: Valeur brute du camion | I27: =Avril!C45 -> 36000
B28: Total | C28: =SUM(C26:C27) -> 2 | E28: Marge sur coûts variables | F28: =SUM(F26:F27) -> 40000 | H28: - Amortissements cumulés | I28: =Avril!C46+F32 -> -3000 | K28: EBITDA | L28: =F31 -> 38700
E29: - Salarié | F29: =-C14 -> -1000 | H29: Valeur nette du camion | I29: =I27+I28 -> 33000 | K29: - Augmentation des stocks | L29: =-(I30-Avril!C48) -> -500
E30: - Assurance camion | F30: =-C15 -> -300 | H30: Stocks | I30: =Avril!C48+C9-C12*C4 -> 500 | K30: - Augmentation des créances clients | L30: =-(I33-Avril!C49) -> -50000
E31: EBITDA | F31: =SUM(F28:F30) -> 38700 | H31: Créances clients avril | I31: =Avril!C49 -> 40000 | K31: + Augmentation des dettes fournisseurs | L31: =I44-Avril!F50 -> 4000
E32: - Amortissement camion | F32: =Avril!C38 -> -1000 | H32: Créances clients mai | I32: =F26 -> 50000 | K32: - Impôts | L32: =F36 -> -12500
E33: EBIT (Résultat d'exploitation) | F33: =SUM(F31:F32) -> 37700 | H33: Créances clients (total) | I33: =I31+I32 -> 90000 | K33: Flux de trésorerie d'exploitation | L33: =SUM(L28:L32) -> -20300
E34: - Intérêts d'emprunt | F34: =-C18*C19 -> -200 | H34: Disponibilités | I34: =L43 -> 3900
E35: Bénéfice avant impôts | F35: =SUM(F33:F34) -> 37500 | H35: Total actif | I35: =I29+I30+I33+I34 -> 127400 | K35: Flux de trésorerie d'investissement | L35: 0
E36: - Impôts | F36: =-C22*F35 -> -12500
E37: Bénéfice net mensuel | F37: =SUM(F35:F36) -> 25000 | K37: Emprunt auprès d'Alpha-Bank | L37: =C18 -> 20000
H38: PASSIF | K38: Intérêts d'emprunt | L38: =F34 -> -200
E39: EBITDA: Earnings Before Interest, Tax, Depreciation & Amortization | H39: Capital social | I39: =Avril!F45 -> 5000 | K39: Flux de trésorerie de financement | L39: =SUM(L37:L38) -> 19800
E40: EBIT: Earnings Before Interest & Tax | H40: Réserves | I40: =Avril!F46+Avril!F47 -> 73400
H41: Bénéfice net mensuel | I41: =F37 -> 25000 | K41: Flux de trésorerie total | L41: =L33+L35+L39 -> -500
H42: Capitaux propres | I42: =SUM(I39:I41) -> 103400
H43: Emprunt auprès d'Alpha-Bank | I43: =C18 -> 20000 | K43: Disponibilités de fin | L43: =L26+L41 -> 3900
H44: Dettes fournisseurs | I44: =C9/2 -> 4000
H45: Total passif | I45: =I42+I43+I44 -> 127400
E49: Marge opérationnelle | F49: =F33/F26 -> 0.754 | H49: Ressources employées par l'exploitation : | K49: EBIT * (1-Taux imposition) | L49: =F33*(1-C22) -> 25133.333
H50: =H29 -> Valeur nette du camion | I50: =I29 -> 33000 | K50: + Amortissement | L50: =-F32 -> 1000
H51: Stocks | I51: =I30 -> 500 | K51: - Investissement dans BFR | L51: =-(I54-(Avril!C48+Avril!C49-Avril!F50)) -> -46500
...

Sheet Sensibilité blank
B1: ANALYSE DE SENSIBILITE (MAI)
E5: Marge opérationnelle | F5: ROCE
C6: 0 | D6: Scenario de départ
C7: =C6+1 -> 1 | D7: Quantité vendue /2
C8: =C7+1 -> 2 | D8: Prix de vente /2
C9: =C8+1 -> 3 | D9: Coût des matières premières *2
C10: =C9+1 -> 4 | D10: Coût de l'eau et de l'électricité *2
C11: =C10+1 -> 5 | D11: Coûts fixes *2
C12: =C11+1 -> 6 | D12: Taux d'intérêt *2
C13: =C12+1 -> 7 | D13: Immobilisations nettes *2
C14: =C13+1 -> 8 | D14: Stocks *2
C15: =C14+1 -> 9 | D15: Créances clients *2
C16: =C15+1 -> 10 | D16: Dettes fournisseurs /2

Sheet Sensibilité
B1: ANALYSE DE SENSIBILITE (MAI)
E5: Marge opérationnelle | F5: ROCE
C6: 0 | D6: Scenario de départ | E6: =Mai!F33/Mai!F26 -> 0.754 | F6: =Mai!F33/(Mai!I29+Mai!I30+Mai!I33-Mai!I44) -> 0.31548117
C7: =C6+1 -> 1 | D7: Quantité vendue /2 | E7: 0.708 | F7: 0.18015267
C8: =C7+1 -> 2 | D8: Prix de vente /2 | E8: 0.508 | F8: 0.13439153
C9: =C8+1 -> 3 | D9: Coût des matières premières *2 | E9: 0.604 | F9: 0.26964286
C10: =C9+1 -> 4 | D10: Coût de l'eau et de l'électricité *2 | E10: 0.704 | F10: 0.29456067
C11: =C10+1 -> 5 | D11: Coûts fixes *2 | E11: 0.708 | F11: 0.299
C12: =C11+1 -> 6 | D12: Taux d'intérêt *2 | E12: 0.754 | F12: 0.31548117
C13: =C12+1 -> 7 | D13: Immobilisations nettes *2 | E13: 0.754 | F13: 0.24721311
C14: =C13+1 -> 8 | D14: Stocks *2 | E14: 0.754 | F14: 0.31416667
C15: =C14+1 -> 9 | D15: Créances clients *2 | E15: 0.754 | F15: 0.18
C16: =C15+1 -> 10 | D16: Dettes fournisseurs /2 | E16: 0.754 | F16: 0.31
